<!--
Copyright 2025 Google LLC

Licensed under the Apache License, Version 2.0 (the "License");
you may not use this file except in compliance with the License.
You may obtain a copy of the License at

    https://www.apache.org/licenses/LICENSE-2.0

Unless required by applicable law or agreed to in writing, software
distributed under the License is distributed on an "AS IS" BASIS,
WITHOUT WARRANTIES OR CONDITIONS OF ANY KIND, either express or implied.
See the License for the specific language governing permissions and
limitations under the License.
-->

<mujoco model="so100_scene">
  <compiler angle="radian" autolimits="true"/>
  
  <option cone="elliptic" impratio="10"/>
  
  <asset>
    <!-- Scene materials -->
    <material name="table_material" rgba="0.8 0.6 0.4 1.0"/>
    <material name="floor_material" rgba="0.3 0.3 0.3 1.0"/>
    <material name="so100_material" rgba="0.7 0.7 0.7 1.0"/>
    <material name="gripper_material" rgba="0.3 0.3 0.3 1.0"/>
    
  </asset>

  <default>
    <default class="so100">
      <joint axis="0 0 1" actuatorfrcrange="-50 50"/>
      <site group="4"/>
      <default class="rotation">
        <joint axis="0 0 1" range="-3.14159 3.14159" damping="5.0"/>
        <position ctrlrange="-3.14159 3.14159" kp="50"/>
      </default>
      <default class="pitch">
        <joint axis="0 1 0" range="-1.57 1.57" damping="10.0"/>
        <position ctrlrange="-1.57 1.57" kp="100"/>
      </default>
      <default class="elbow">
        <joint axis="0 1 0" range="-2.0 2.0" damping="8.0"/>
        <position ctrlrange="-2.0 2.0" kp="80"/>
      </default>
      <default class="wrist_pitch">
        <joint axis="0 1 0" range="-1.57 1.57" damping="5.0"/>
        <position ctrlrange="-1.57 1.57" kp="40"/>
      </default>
      <default class="wrist_roll">
        <joint axis="1 0 0" range="-3.14159 3.14159" damping="2.0"/>
        <position ctrlrange="-3.14159 3.14159" kp="20"/>
      </default>
      <default class="jaw">
        <joint axis="0 0 1" range="0 0.08" damping="1.0"/>
        <position ctrlrange="0 0.08" kp="100"/>
      </default>
      <default class="visual">
        <geom type="box" contype="0" conaffinity="0" density="0" group="2" material="so100_material"/>
      </default>
      <default class="collision">
        <geom group="3" type="box"/>
      </default>
    </default>
  </default>
  
  <visual>
    <headlight ambient="0.4 0.4 0.4" diffuse="0.8 0.8 0.8" specular="0.1 0.1 0.1"/>
    <rgba haze="0.15 0.25 0.35 1"/>
    <global offwidth="640" offheight="480"/>
  </visual>
  
  <worldbody>
    <!-- Lighting -->
    <light name="top_light" pos="0 0 2" dir="0 0 -1" diffuse="0.8 0.8 0.8" ambient="0.2 0.2 0.2"/>
    <light name="side_light1" pos="1 1 1.5" dir="-1 -1 -1" diffuse="0.4 0.4 0.4"/>
    <light name="side_light2" pos="-1 1 1.5" dir="1 -1 -1" diffuse="0.4 0.4 0.4"/>
    
    <!-- Floor -->
    <geom name="floor" type="plane" size="3 3 0.1" material="floor_material" friction="1 0.005 0.0001"/>
    
    <!-- Table -->
    <body name="table" pos="0 0 0.4">
      <geom name="table_top" type="box" size="0.5 0.4 0.02" pos="0 0 0" material="table_material"/>
      <!-- Table legs -->
      <geom name="leg1" type="cylinder" size="0.02 0.2" pos="0.45 0.35 -0.2" material="table_material"/>
      <geom name="leg2" type="cylinder" size="0.02 0.2" pos="0.45 -0.35 -0.2" material="table_material"/>
      <geom name="leg3" type="cylinder" size="0.02 0.2" pos="-0.45 0.35 -0.2" material="table_material"/>
      <geom name="leg4" type="cylinder" size="0.02 0.2" pos="-0.45 -0.35 -0.2" material="table_material"/>
    </body>
    
    <!-- Cameras -->
    <camera name="overhead_cam" pos="0 0 1.5" xyaxes="1 0 0 0 1 0" fovy="45"/>
    <camera name="worms_eye_cam" pos="0 0 0.1" xyaxes="1 0 0 0 0 1" fovy="45"/>
    <camera name="side_cam" pos="1.2 0.8 0.8" xyaxes="-0.8 0.6 0 -0.36 -0.48 0.8" fovy="45"/>
    
    <!-- SO100 ARM placed on the table -->
    <body name="so100/base_link" childclass="so100" pos="0 0 0.42">
      <inertial pos="0 0 0.05" mass="2.0" diaginertia="0.01 0.01 0.01"/>
      <geom name="base_visual" type="box" size="0.05 0.05 0.05" pos="0 0 0.05" contype="0" conaffinity="0" density="0" group="2" rgba="0.7 0.7 0.7 1.0"/>
      <geom name="base_collision" type="box" size="0.05 0.05 0.05" pos="0 0 0.05" group="3"/>
      
      <body name="so100/shoulder_link" pos="0 0 0.1">
        <inertial pos="0 0 0.05" mass="1.5" diaginertia="0.005 0.005 0.005"/>
        <joint name="so100/rotation" axis="0 0 1" range="-3.14159 3.14159" damping="5.0" actuatorfrcrange="-50 50"/>
        <geom name="shoulder_visual" type="box" size="0.04 0.04 0.05" pos="0 0 0.05" contype="0" conaffinity="0" density="0" group="2" rgba="0.7 0.7 0.7 1.0"/>
        <geom name="shoulder_collision" type="box" size="0.04 0.04 0.05" pos="0 0 0.05" group="3"/>
        
        <body name="so100/upper_arm_link" pos="0 0 0.1">
          <inertial pos="0 0 0.1" mass="1.2" diaginertia="0.01 0.01 0.002"/>
          <joint name="so100/pitch" axis="0 1 0" range="-1.57 1.57" damping="10.0" actuatorfrcrange="-50 50"/>
          <geom name="upper_arm_visual" type="box" size="0.03 0.03 0.1" pos="0 0 0.1" contype="0" conaffinity="0" density="0" group="2" rgba="0.7 0.7 0.7 1.0"/>
          <geom name="upper_arm_collision" type="box" size="0.03 0.03 0.1" pos="0 0 0.1" group="3"/>
          
          <body name="so100/forearm_link" pos="0 0 0.2">
            <inertial pos="0 0 0.08" mass="0.8" diaginertia="0.005 0.005 0.001"/>
            <joint name="so100/elbow" axis="0 1 0" range="-2.0 2.0" damping="8.0" actuatorfrcrange="-50 50"/>
            <geom name="forearm_visual" type="box" size="0.025 0.025 0.08" pos="0 0 0.08" contype="0" conaffinity="0" density="0" group="2" rgba="0.7 0.7 0.7 1.0"/>
            <geom name="forearm_collision" type="box" size="0.025 0.025 0.08" pos="0 0 0.08" group="3"/>
            
            <body name="so100/wrist_link" pos="0 0 0.16">
              <inertial pos="0 0 0.03" mass="0.4" diaginertia="0.001 0.001 0.001"/>
              <joint name="so100/wrist_pitch" axis="0 1 0" range="-1.57 1.57" damping="5.0" actuatorfrcrange="-50 50"/>
              <geom name="wrist_visual" type="box" size="0.02 0.02 0.03" pos="0 0 0.03" contype="0" conaffinity="0" density="0" group="2" rgba="0.7 0.7 0.7 1.0"/>
              <geom name="wrist_collision" type="box" size="0.02 0.02 0.03" pos="0 0 0.03" group="3"/>
              
              <body name="so100/hand_link" pos="0 0 0.06">
                <inertial pos="0 0 0.02" mass="0.2" diaginertia="0.0005 0.0005 0.0005"/>
                <joint name="so100/wrist_roll" axis="1 0 0" range="-3.14159 3.14159" damping="2.0" actuatorfrcrange="-50 50"/>
                <geom name="hand_visual" type="box" size="0.015 0.015 0.02" pos="0 0 0.02" contype="0" conaffinity="0" density="0" group="2" rgba="0.7 0.7 0.7 1.0"/>
                <geom name="hand_collision" type="box" size="0.015 0.015 0.02" pos="0 0 0.02" group="3"/>
                
                <site name="so100/gripper" pos="0 0 0.04" group="5"/>
                
                <body name="so100/gripper_left" pos="0.02 0 0.04">
                  <inertial pos="0 0 0.015" mass="0.05" diaginertia="0.0001 0.0001 0.0001"/>
                  <joint name="so100/jaw_left" axis="0 0 1" range="0 0.08" damping="1.0" actuatorfrcrange="-50 50"/>
                  <geom name="gripper_left_visual" type="box" size="0.005 0.01 0.015" contype="0" conaffinity="0" density="0" group="2" rgba="0.3 0.3 0.3 1.0"/>
                  <geom name="gripper_left_collision" type="box" size="0.005 0.01 0.015" group="3"/>
                </body>
                
                <body name="so100/gripper_right" pos="-0.02 0 0.04">
                  <inertial pos="0 0 0.015" mass="0.05" diaginertia="0.0001 0.0001 0.0001"/>
                  <joint name="so100/jaw_right" axis="0 0 1" range="0 0.08" damping="1.0" actuatorfrcrange="-50 50"/>
                  <geom name="gripper_right_visual" type="box" size="0.005 0.01 0.015" contype="0" conaffinity="0" density="0" group="2" rgba="0.3 0.3 0.3 1.0"/>
                  <geom name="gripper_right_collision" type="box" size="0.005 0.01 0.015" group="3"/>
                </body>
              </body>
            </body>
          </body>
        </body>
      </body>
    </body>
  </worldbody>

  <contact>
    <exclude body1="so100/base_link" body2="so100/shoulder_link"/>
  </contact>

  <equality>
    <joint joint1="so100/jaw_left" joint2="so100/jaw_right" polycoef="0 1 0 0 0"/>
  </equality>

  <actuator>
    <position name="so100/rotation_actuator" joint="so100/rotation" ctrlrange="-3.14159 3.14159" kp="50"/>
    <position name="so100/pitch_actuator" joint="so100/pitch" ctrlrange="-1.57 1.57" kp="100"/>
    <position name="so100/elbow_actuator" joint="so100/elbow" ctrlrange="-2.0 2.0" kp="80"/>
    <position name="so100/wrist_pitch_actuator" joint="so100/wrist_pitch" ctrlrange="-1.57 1.57" kp="40"/>
    <position name="so100/wrist_roll_actuator" joint="so100/wrist_roll" ctrlrange="-3.14159 3.14159" kp="20"/>
    <position name="so100/jaw_actuator" joint="so100/jaw_left" ctrlrange="0 0.08" kp="100"/>
  </actuator>

  <keyframe>
    <key name="neutral_pose" qpos="0 -0.5 1.0 -0.5 0.0 0.02 0.02"/>
  </keyframe>
</mujoco>