<!--
Copyright 2025 Google LLC

Licensed under the Apache License, Version 2.0 (the "License");
you may not use this file except in compliance with the License.
You may obtain a copy of the License at

    https://www.apache.org/licenses/LICENSE-2.0

Unless required by applicable law or agreed to in writing, software
distributed under the License is distributed on an "AS IS" BASIS,
WITHOUT WARRANTIES OR CONDITIONS OF ANY KIND, either express or implied.
See the License for the specific language governing permissions and
limitations under the License.
-->

<mujoco model="mk1157_counter">
  <compiler meshdir="meshes" angle="radian" autolimits="true"/>
  <asset>
    <mesh name="mk1157_counter_collision_01" file="mk1157_counter_collision_01.stl" scale="0.4 0.23 0.1"/>
    <mesh name="mk1157_counter_collision_02" file="mk1157_counter_collision_02.stl" scale="0.4 0.23 0.1"/>
    <mesh name="mk1157_counter_collision_03" file="mk1157_counter_collision_03.stl" scale="0.4 0.23 0.1"/>
    <mesh name="mk1157_counter_collision_04" file="mk1157_counter_collision_04.stl" scale="0.4 0.23 0.1"/>
    <mesh name="mk1157_counter_collision_05" file="mk1157_counter_collision_05.stl" scale="0.4 0.23 0.1"/>
    <mesh name="mk1157_counter_collision_06" file="mk1157_counter_collision_06.stl" scale="0.4 0.23 0.1"/>
    <mesh name="mk1157_counter_collision_07" file="mk1157_counter_collision_07.stl" scale="0.4 0.23 0.1"/>
    <mesh name="mk1157_drawer_collision_01" file="mk1157_drawer_collision_01.stl" scale="0.37 0.23 0.15"/>
    <mesh name="mk1157_drawer_collision_02" file="mk1157_drawer_collision_02.stl" scale="0.37 0.23 0.15"/>
    <mesh name="mk1157_drawer_collision_03" file="mk1157_drawer_collision_03.stl" scale="0.37 0.23 0.15"/>
    <mesh name="mk1157_drawer_collision_04" file="mk1157_drawer_collision_04.stl" scale="0.37 0.23 0.15"/>
    <mesh name="mk1157_drawer_collision_05" file="mk1157_drawer_collision_05.stl" scale="0.37 0.23 0.15"/>
  </asset>
  <worldbody>
   <body name="drawer" pos="0 0 0">
   <freejoint/>
    <geom type="mesh" name="counter_top" rgba="0.4 0.4 0.4 1" mesh="mk1157_counter_collision_01"/>
    <geom type="mesh" name="counter_bottom" rgba="0.4 0.4 0.4 1" mesh="mk1157_counter_collision_02"/>
    <geom type="mesh" name="counter_right"  rgba="0.4 0.4 0.4 1" mesh="mk1157_counter_collision_03"/>
    <geom type="mesh" name="counter_back"   rgba="0.4 0.4 0.4 1" mesh="mk1157_counter_collision_05"/>
    <geom type="mesh" name="counter_left"   rgba="0.4 0.4 0.4 1" mesh="mk1157_counter_collision_06"/>
    <body name="link_top_drawer_low" pos="0 0 0.068">
      <joint name="joint_top_drawer_low" pos="0 0 0" axis="0 -1 0" type="slide" range="0 0.1" damping="5"/>
      <geom type="cylinder" rgba="0.4 0.4 0.4 1" size="0.002 0.002" density="200" pos="0.0 -0.075 0" quat=".707107 -0.707107 0 0"/>
      <geom type="sphere" rgba="0.8 0.8 0.8 1" size="0.005" density="200" pos="0.0 -0.08 0" quat=".707107 -0.707107 0 0"/>
      <site name="top_handle" pos="0 -0.3 0.08" size="0.005 0.005 0.005" rgba="1 .1 .1 .3" group="3"/>
      <geom type="mesh" rgba="0.4 0.4 0.4 1" mesh="mk1157_drawer_collision_01" density="200"/>
      <geom type="mesh" rgba="0.4 0.4 0.4 1" mesh="mk1157_drawer_collision_02" density="200"/>
      <geom type="mesh" rgba="0.4 0.4 0.4 1" mesh="mk1157_drawer_collision_03" density="200"/>
      <geom type="mesh" rgba="0.4 0.4 0.4 1" mesh="mk1157_drawer_collision_04" density="200"/>
      <geom type="mesh" name="top" rgba="0.4 0.4 0.4 1" mesh="mk1157_drawer_collision_05" density="200"/>
    </body>
    <body name="link_middle_drawer_low" pos="0 0 0.04">
      <joint name="joint_middle_drawer_low" pos="0 0 0" axis="0 -1 0" type="slide" range="0 0.1" damping="5"/>
      <geom type="cylinder" rgba="0.4 0.4 0.4 1" size="0.002 0.002" density="200" pos="0.0 -0.075 0" quat=".707107 -0.707107 0 0"/>
      <geom type="sphere" rgba="0.8 0.8 0.8 1" size="0.005" density="200" pos="0.0 -0.08 0" quat=".707107 -0.707107 0 0"/>
      <site name="mid_handle" pos="0 -0.35 0.05" size="0.005 0.005 0.005" rgba="1 .1 .1 .3" group="3"/>
      <geom type="mesh" rgba="0.4 0.4 0.4 1" mesh="mk1157_drawer_collision_01" density="200"/>
      <geom type="mesh" rgba="0.4 0.4 0.4 1" mesh="mk1157_drawer_collision_02" density="200"/>
      <geom type="mesh" rgba="0.4 0.4 0.4 1" mesh="mk1157_drawer_collision_03" density="200"/>
      <geom type="mesh" rgba="0.4 0.4 0.4 1" mesh="mk1157_drawer_collision_04" density="200"/>
      <geom type="mesh" rgba="0.4 0.4 0.4 1" mesh="mk1157_drawer_collision_05" density="200"/>
    </body>
    <body name="link_bottom_drawer_low" pos="0 0 0.012">
      <joint name="joint_bottom_drawer_low" pos="0 0 0" axis="0 -1 0" type="slide" range="0 0.1" damping="5"/>
      <geom type="cylinder" rgba="0.4 0.4 0.4 1" size="0.002 0.002" density="200" pos="0.0 -0.075 0" quat=".707107 -0.707107 0 0"/>
      <geom type="sphere" rgba="0.8 0.8 0.8 1" size="0.005" density="200" pos="0.0 -0.08 0" quat=".707107 -0.707107 0 0"/>
      <geom type="mesh" rgba="0.4 0.4 0.4 1" mesh="mk1157_drawer_collision_01" density="200"/>
      <geom type="mesh" rgba="0.4 0.4 0.4 1" mesh="mk1157_drawer_collision_02" density="200"/>
      <geom type="mesh" rgba="0.4 0.4 0.4 1" mesh="mk1157_drawer_collision_03" density="200"/>
      <geom type="mesh" rgba="0.4 0.4 0.4 1" mesh="mk1157_drawer_collision_04" density="200"/>
      <geom type="mesh" rgba="0.4 0.4 0.4 1" mesh="mk1157_drawer_collision_05" density="200"/>
    </body>
   </body>
  </worldbody>
</mujoco>
